Workbook
Name _SA79: '[1]Comparison-Other Exp_Feb07'!$AM$1:$AM$65536
Name abc: #REF!
Name abc: #REF!
Name abc: #REF!
Name abc: #REF!
Name Asset_Register: #REF!
Name Asset_Register: #REF!
Name Asset_Register: #REF!
Name Asset_Register: #REF!
Name balance_sheet: #REF!
Name balance_sheet: #REF!
Name balance_sheet: #REF!
Name balance_sheet: #REF!
Name bd: '[1]Staff Cost_Jan07'!$AL$12
Name BS: #REF!
Name BS: #REF!
Name BS: #REF!
Name BS: #REF!
Name bv: #REF!
Name bv: #REF!
Name bv: #REF!
Name bv: #REF!
Name cr_acc_acc: #REF!
Name cr_acc_acc: #REF!
Name cr_acc_acc: #REF!
Name cr_acc_acc: #REF!
Name pl: #REF!
Name pl: #REF!
Name pl: #REF!
Name Print_Area_MI: #REF!
Name Print_Area_MI: #REF!
Name Print_Area_MI: #REF!
Name Print_Area_MI: #REF!
Name Print_Titles_MI: #REF!
Name Print_Titles_MI: #REF!
Name Print_Titles_MI: #REF!
Name Print_Titles_MI: #REF!
Name sa: #REF!
Name Sel_Area: [2]Sum_THB!$M$207:$M$212
Name Sel_Brand: [2]Sum_THB!$G$207:$G$225
Name Sel_BrandAffil: [2]Sum_THB!$H$207:$H$210
Name Sel_BusType: [2]Sum_THB!$I$207:$I$210
Name Sel_City: [2]Sum_THB!$J$207:$J$239
Name Sel_Country: [2]Sum_THB!$K$207:$K$219
Name Sel_InvestCat: [2]Sum_THB!$P$207:$P$210
Name Sel_MainCat: [2]Sum_THB!$N$207:$N$210
Name Sel_OpYear: [2]Sum_THB!$F$207:$F$209
Name Sel_OtherCat: [2]Sum_THB!$Q$207:$Q$212
Name Sel_Region: [2]Sum_THB!$L$207:$L$218
Name Sel_StatusCat: [2]Sum_THB!$O$207:$O$213
Name Summary: #REF!
Name Summary: #REF!
Name Summary: #REF!
Name Summary: #REF!

Sheet 1.契約要目表
A1: 契約要目表
A2: 発注期間 | D2: 2025年1月1日~2025年12月31日
A3: 開発場所 | D3: BIP SYSTEMS Vitenam社内
A4: 単価 | B4: PG/テスター | C4: 定義 | D4: ソフトウェア開発業務に0~2年以上従事した経験があり、要求業務を実行できる。
C5: 単金 | D5: 25万円/人月
B6: SE | C6: 要件 | D6: ソフトウェア開発業務に2年以上従事した経験があり、相応の実力が認められる。
C7: 単金 | D7: 30.0万円/人月
B8: PL | C8: 定義 | D8: ソフトウェア開発業務に3年以上従事した経験があり、かつプロジェクトリーダーとして十分な能力が認められるもの
C9: 単金 | D9: 43万円/人月
B10: コミュニケータ（CM) | C10: 定義 | D10: 通訳として、PM,PLを補佐しプロジェクト管理支援を行う
C11: 単金 | D11: 30万円/人月(2,700USD)
B12: PM | C12: 定義 | D12: ソフトウェア開発経験年数5年以上及びプロジェクトリーダとして3年以上、さらにマネジメント経験が3年以上。
C13: 単金 | D13: 60万円/人月
A14: 為替基準 | D14: 1USD=130円
A15: 支払通貨 | D15: 日本円
A16: 指定要員(請求に関連する要員27名) | C16: 日本人PM | D16: 柏木武志
C18: PS_PM | D18: Nguyen Tien Dung(2024/9/1入社)
C20: PL | D20: Kieu Bao Long
C22: PL | D22: Tran Tuan Long
C24: PS_PG | D24: Tran Phuc Hong
C26: SE | D26: Nguyen Minh Vu
C28: SE | D28: Bui Thi Thom
C30: PS_SE | D30: Nguyen Tien Trung(2024/9/1入社)
C32: PS_SE | D32: Nguyen Anh Tuan(2024/9/1入社)
C34: SE | D34: Ngyurn Thanh Minh
C36: SE | D36: Ngyuen Thanh Trung
C38: SE | D38: Pham Long Quan
C40: SE | D40: Do Tuan Thanh
... C68: CM | D68: Hoang Thi Ngoc Dung (2024/11/4入社)
A70: 報告頻度
A71: 備考 | D71: 1. 単金については毎年1月に見直す 2. 乙の指定要員に変更がある場合は、乙は甲に速やかに、その旨を通知する

Sheet 注
B3: シート | C3: 氏名 | D3: 金額 | E3: 計算方法
B4: Sep_24 | C4: Do Huu Tuan | D4: 111905 | E4: 単金470,000円×5/21（9月25日入社,稼働日数5日,9月営業日数は21日）
C5: Nguyen Tuan Anh | D5: 102273 | E5: 単金250,000円×9/22（9月18日入社,稼働日数9日,9月営業日数は22日）
B6: Oct_24 | C6: Lai Nguyen Que Chi | D6: 54545 | E6: 単金300,000円×4/22（10月28日入社,稼働日数4日,10月営業日数は22日）
B7: Nov_24 | C7: Do Huu Tuan | D7: 270611 | E7: 退職に伴う日割り268,571円：単金470,000円×12/21（11月18日まで在職で稼働日数12日,11月営業日数は21日）
E8: 残業 2,040円：2.5時間、時間あたり816円
E9: →270,611=268,571+2,040
C10: Ngyuen Tien Trung | D10: 312400 | E10: 単金300,000円に残業3.5時間分2,400円が追加
F13: =470000*0.57 -> 267900
F14: =12/21 -> 0.57142857

Sheet 2.Sep_24 
A1: 45565
A4: ビップシステムズ株式会社殿 | H4: 45679
A6: 下記のとおり実施しましたので報告致します．
B7: 記
A9: 1 | B9: 報告期間 | C9: 2024年9月1日～9月30日
A12: 2 | B12: 作業報告書及びご請求金額 | J12: (単位：円・時間)
B13: 要員名 | C13: ランク | D13: 区分 | E13: 契約単金(上段：月額、下段：時間単価） | F13: 時間外稼働 | G13: 業務内容 | H13: 計
B14: 柏木武志 | C14: JPM | D14: 月額単金 | E14: 600000 | F14: 0 | G14: TX様ODC契約内プロジェクト、RSS東西、VACのプロジェクトマネジメント | H14: =E14 -> 600000
D15: 普通残業
B16: Nguyen Tien Dung | C16: PS_GM | D16: 月額単金 | G16: SFDCの2プロジェクト（WOWOWとNGB）でのマネジメント | H16: =E16 -> 0
D17: 普通残業 | F17: 0
B18: Kieu Bao Long | C18: PL | D18: 月額単金 | G18: 音声マイニングシステム機能追加とプロジェクトマネジメント | H18: =E18 -> 0
D19: 普通残業 | F19: 0
B20: Tran Tuan Long | C20: PL | D20: 月額単金 | G20: mietenプロジェクトリーダ、CiMAプロジェクトマネジメント | H20: =E20 -> 0
D21: 普通残業 | F21: 0
B22: Do Huu Tuan | C22: PS_PM | D22: 月額単金 | G22: SFDC,WOWOWプロジェクトの開発PM | H22: =E22*5/21 -> 0
D23: 普通残業 | F23: 0
B24: Ngyuen Tien Trung | C24: PS_PL | D24: 月額単金 | G24: SFDC,NGBプロジェクトの開発リーダ | H24: =E24 -> 0
D25: 普通残業 | F25: 0
B26: Nguyen Anh Tuan | C26: PS_SE | D26: 月額単金 | G26: SFDC,NGBプロジェクトの開発 | H26: =E26 -> 0
D27: 普通残業 | F27: 0
B28: Nguyen Minh Vu | C28: SE | D28: 月額単金 | G28: 音声マイニングシステム機能追加 | H28: =E28 -> 0
D29: 普通残業 | F29: 0
B30: Bui Thi Thom | C30: SE | D30: 月額単金 | G30: ドコモ通知機能開発 | H30: =E30 -> 0
D31: 普通残業 | F31: 0
B32: Ngyurn Thanh Minh | C32: SE | D32: 月額単金 | G32: RSS東西システム更改開発 | H32: =E32 -> 0
D33: 普通残業 | F33: 0
B34: Ngyuen Thanh Trung | C34: SE | D34: 月額単金 | G34: ドコモ通知機能開発 | H34: =E34 -> 0
D35: 普通残業 | F35: 0
B36: Pham Long Quan | C36: SE | D36: 月額単金 | G36: 本社向け人事管理処理機能の自動化 | H36: =E36 -> 0
D37: 普通残業 | F37: 0
B38: Do Tuan Thanh | C38: SE | D38: 月額単金 | G38: 音声マイニングシステム機能追加 | H38: =E38 -> 0
D39: 普通残業 | F39: 0
B40: Bui Hong Khnah | C40: SE | D40: 月額単金 | G40: 興研機能追加 | H40: =E40 -> 0
D41: 普通残業 | F41: 0
B42: Nguyen Hai Anh | C42: PG | D42: 月額単金 | G42: CiMAプロジェクトUT実施 | H42: =E42 -> 0
D43: 普通残業 | F43: 0
B44: Hoang Quang Linh | C44: PG | D44: 月額単金 | F44: 0 | G44: 音声マイニングシステム機能追加 | H44: =E44 -> 0
D45: 普通残業
B46: Luu Thi Hai Yen | C46: PG | D46: 月額単金 | F46: 0 | G46: CiMAプロジェクトUT実施 | H46: =E46 -> 0
...

Sheet 2.Oct_24
A1: 45596 | B1: 41698 | C1: 41698 | G1: 41698 | H1: 41698 | I1: 41698 | J1: 41698
A4: ビップシステムズ株式会社殿 | H4: 45679
A6: 下記のとおり実施しましたので報告致します．
B7: 記
A9: 1 | B9: 報告期間 | C9: 2024年10月1日～10月31日
A12: 2 | B12: 作業報告書及びご請求金額 | J12: (単位：円・時間)
B13: 要員名 | C13: ランク | D13: 区分 | E13: 契約単金(上段：月額、下段：時間単価） | F13: 時間外稼働 | G13: 業務内容 | H13: 計
B14: 柏木武志 | C14: JPM | D14: 月額単金 | F14: 0 | G14: TX様ODC契約内プロジェクト、RSS東西、VACのプロジェクトマネジメント | H14: =E14 -> 0
D15: 普通残業
B16: Nguyen Tien Dung | C16: PS_GM | D16: 月額単金 | G16: SFDCの2プロジェクト（WOWOWとNGB）でのマネジメント | H16: =E16 -> 0
D17: 普通残業 | F17: 0
B18: Kieu Bao Long | C18: PL | D18: 月額単金 | G18: 音声マイニングシステム機能追加とプロジェクトマネジメント | H18: =E18 -> 0
D19: 普通残業 | F19: 0
B20: Tran Tuan Long | C20: PL | D20: 月額単金 | G20: mietenプロジェクトリーダ、CiMAプロジェクトマネジメント | H20: =E20 -> 0
D21: 普通残業 | F21: 0
B22: Do Huu Tuan | C22: PS_PM | D22: 月額単金 | G22: SFDC,WOWOWプロジェクトの開発PM | H22: =E22 -> 0
D23: 普通残業 | F23: 0
B24: Ngyuen Tien Trung | C24: PS_PL | D24: 月額単金 | G24: SFDC,NGBプロジェクトの開発リーダ | H24: =E24 -> 0
D25: 普通残業 | F25: 0
B26: Nguyen Anh Tuan | C26: PS_SE | D26: 月額単金 | G26: SFDC,NGBプロジェクトの開発 | H26: =E26 -> 0
D27: 普通残業 | F27: 0
B28: Nguyen Minh Vu | C28: SE | D28: 月額単金 | G28: 音声マイニングシステム機能追加 | H28: =E28 -> 0
D29: 普通残業 | F29: 0
B30: Bui Thi Thom | C30: SE | D30: 月額単金 | G30: ドコモ通知機能開発 | H30: =E30 -> 0
D31: 普通残業 | F31: 0
B32: Ngyurn Thanh Minh | C32: SE | D32: 月額単金 | G32: RSS東西システム更改開発 | H32: =E32 -> 0
D33: 普通残業 | F33: 0
B34: Ngyuen Thanh Trung | C34: SE | D34: 月額単金 | G34: ドコモ通知機能開発 | H34: =E34 -> 0
D35: 普通残業 | F35: 0
B36: Pham Long Quan | C36: SE | D36: 月額単金 | F36: 0 | G36: 本社向け人事管理処理機能の自動化 | H36: =E36 -> 0
D37: 普通残業
B38: Do Tuan Thanh | C38: SE | D38: 月額単金 | F38: 0 | G38: 音声マイニングシステム機能追加 | H38: =E38 -> 0
D39: 普通残業
B40: Bui Hong Khnah | C40: SE | D40: 月額単金 | F40: 0 | G40: 興研機能追加 | H40: =E40 -> 0
D41: 普通残業
B42: Nguyen Hai Anh | C42: PG | D42: 月額単金 | G42: CiMAプロジェクトUT実施 | H42: =E42 -> 0
D43: 普通残業 | F43: 0
B44: Hoang Quang Linh | C44: PG | D44: 月額単金 | G44: 音声マイニングシステム機能追加 | H44: =E44 -> 0
D45: 普通残業 | F45: 0
B46: Luu Thi Hai Yen | C46: PG | D46: 月額単金 | G46: CiMAプロジェクトUT実施 | H46: =E46 -> 0
...

Sheet 2.Nov_24
A1: 45626 | B1: 41698 | C1: 41698 | G1: 41698 | H1: 41698 | I1: 41698 | J1: 41698
A4: ビップシステムズ株式会社殿 | H4: 45679
A6: 下記のとおり実施しましたので報告致します．
B7: 記
A9: 1 | B9: 報告期間 | C9: 2024年11月1日～11月30日
A12: 2 | B12: 作業報告書及びご請求金額 | J12: (単位：円・時間)
B13: 要員名 | C13: ランク | D13: 区分 | E13: 契約単金(上段：月額、下段：時間単価） | F13: 時間外稼働 | G13: 業務内容 | H13: 計
B14: 柏木武志 | C14: JPM | D14: 月額単金 | F14: 0 | G14: TX様ODC契約内プロジェクト、RSS東西、VACのプロジェクトマネジメント | H14: =E14 -> 0
D15: 普通残業
B16: Nguyen Tien Dung | C16: PS_GM | D16: 月額単金 | G16: SFDCの2プロジェクト（WOWOWとNGB）でのマネジメント | H16: =E16 -> 0
D17: 普通残業 | F17: 0
B18: Kieu Bao Long | C18: PL | D18: 月額単金 | G18: 音声マイニングシステム機能追加とプロジェクトマネジメント | H18: =E18 -> 0
D19: 普通残業 | F19: 0
B20: Tran Tuan Long | C20: PL | D20: 月額単金 | G20: mietenプロジェクトリーダ、CiMAプロジェクトマネジメント | H20: =E20 -> 0
D21: 普通残業 | F21: 0
B22: Do Huu Tuan | C22: PS_PM | D22: 月額単金 | G22: SFDC,WOWOWプロジェクトの開発PM | H22: =E22 -> 0
D23: 普通残業 | F23: 2.5
B24: Ngyuen Tien Trung | C24: PS_PL | D24: 月額単金 | G24: SFDC,NGBプロジェクトの開発リーダ | H24: =E24 -> 0
D25: 普通残業 | F25: 0
B26: Nguyen Anh Tuan | C26: PS_SE | D26: 月額単金 | G26: SFDC,NGBプロジェクトの開発 | H26: =E26 -> 0
D27: 普通残業 | F27: 3.5
B28: Nguyen Minh Vu | C28: SE | D28: 月額単金 | G28: 音声マイニングシステム機能追加 | H28: =E28 -> 0
D29: 普通残業 | F29: 0
B30: Bui Thi Thom | C30: SE | D30: 月額単金 | G30: VACシステム開発 | H30: =E30 -> 0
D31: 普通残業 | F31: 0
B32: Ngyurn Thanh Minh | C32: SE | D32: 月額単金 | G32: RSS東西システム更改開発 | H32: =E32 -> 0
D33: 普通残業 | F33: 0
B34: Ngyuen Thanh Trung | C34: SE | D34: 月額単金 | G34: mieten機能追加 | H34: =E34 -> 0
D35: 普通残業 | F35: 0
B36: Pham Long Quan | C36: SE | D36: 月額単金 | G36: 本社向け人事管理処理機能の自動化 | H36: =E36 -> 0
D37: 普通残業 | F37: 0
B38: Do Tuan Thanh | C38: SE | D38: 月額単金 | F38: 0 | G38: 音声マイニングシステム機能追加 | H38: =E38 -> 0
D39: 普通残業
B40: Bui Hong Khnah | C40: SE | D40: 月額単金 | F40: 0 | G40: RSS東西システム更改開発 | H40: =E40 -> 0
D41: 普通残業
B42: Nguyen Anh Duc | C42: SE | D42: 月額単金 | F42: 0 | G42: 音声マイニングシステム機能追加 | H42: =E42 -> 0
D43: 普通残業
B44: Nguyen Hai Anh | C44: PG | D44: 月額単金 | G44: CiMAプロジェクトUT実施 | H44: =E44 -> 0
D45: 普通残業 | F45: 0
B46: Hoang Quang Linh | C46: PG | D46: 月額単金 | G46: 音声マイニングシステム機能追加 | H46: =E46 -> 0
...

Sheet 2.Dec_24
A1: 45657 | B1: 41698 | C1: 41698 | G1: 41698 | H1: 41698 | I1: 41698 | J1: 41698
A4: ビップシステムズ株式会社殿 | H4: 45679
A6: 下記のとおり実施しましたので報告致します．
B7: 記
A9: 1 | B9: 報告期間 | C9: 2024年12月1日～12月31日
A12: 2 | B12: 作業報告書及びご請求金額 | J12: (単位：円・時間)
B13: 要員名 | C13: ランク | D13: 区分 | E13: 契約単金(上段：月額、下段：時間単価） | F13: 時間外稼働 | G13: 業務内容 | H13: 計
B14: 柏木武志 | C14: JPM | D14: 月額単金 | F14: 0 | G14: TX様ODC契約内プロジェクト、RSS東西、VACのプロジェクトマネジメント | H14: =E14 -> 0
D15: 普通残業
B16: Nguyen Tien Dung | C16: PS_GM | D16: 月額単金 | G16: SFDCの2プロジェクト（WOWOWとNGB）でのマネジメント | H16: =E16 -> 0
D17: 普通残業 | F17: 0
B18: Kieu Bao Long | C18: PL | D18: 月額単金 | G18: 音声マイニングシステム機能追加とプロジェクトマネジメント | H18: =E18 -> 0
D19: 普通残業 | F19: 0
B20: Tran Tuan Long | C20: PL | D20: 月額単金 | G20: mietenプロジェクトリーダ、CiMAプロジェクトマネジメント | H20: =E20 -> 0
D21: 普通残業 | F21: 0
B22: Do Huu Tuan | C22: PS_PM | D22: 月額単金 | G22: 退職
D23: 普通残業 | F23: 0
B24: Ngyuen Tien Trung | C24: PS_PL | D24: 月額単金 | G24: SFDC,NGBプロジェクトの開発リーダ | H24: =E24 -> 0
D25: 普通残業 | F25: 0
B26: Ngyuen Minh Quang | C26: PS_PL | D26: 月額単金 | G26: SFDC,WOWOWプロジェクトの開発リーダ | H26: =E26 -> 0
D27: 普通残業 | F27: 0
B28: Nguyen Anh Tuan | C28: PS_SE | D28: 月額単金 | G28: SFDC,NGBプロジェクトの開発 | H28: =E28 -> 0
D29: 普通残業 | F29: 0
B30: Nguyen Minh Vu | C30: SE | D30: 月額単金 | G30: 音声マイニングシステム機能追加 | H30: =E30 -> 0
D31: 普通残業 | F31: 0
B32: Bui Thi Thom | C32: SE | D32: 月額単金 | G32: VACシステム開発 | H32: =E32 -> 0
D33: 普通残業 | F33: 0
B34: Ngyurn Thanh Minh | C34: SE | D34: 月額単金 | G34: RSS東西システム更改開発 | H34: =E34 -> 0
D35: 普通残業 | F35: 0
B36: Ngyuen Thanh Trung | C36: SE | D36: 月額単金 | G36: mieten機能追加 | H36: =E36 -> 0
D37: 普通残業 | F37: 0
B38: Pham Long Quan | C38: SE | D38: 月額単金 | G38: 本社向け人事管理処理機能の自動化 | H38: =E38 -> 0
D39: 普通残業 | F39: 0
B40: Do Tuan Thanh | C40: SE | D40: 月額単金 | F40: 0 | G40: 音声マイニングシステム機能追加 | H40: =E40 -> 0
D41: 普通残業
B42: Bui Hong Khnah | C42: SE | D42: 月額単金 | G42: 興研機能追加 | H42: =E42 -> 0
D43: 普通残業 | F43: 0
B44: Nguyen Anh Duc | C44: SE | D44: 月額単金 | F44: 0 | G44: 音声マイニングシステム機能追加 | H44: =E44 -> 0
D45: 普通残業
B46: Nguyen Hai Anh | C46: PG | D46: 月額単金 | F46: 0 | G46: CiMAプロジェクトUT実施 | H46: =E46 -> 0
...

Sheet 3.請求書
A1: BIP SYSTEMS VIETNAM CO., LTD
A2: Room No 403, DMC Tower 535 Kim Ma Str., Ba Dinh Dist Hanoi | I2: Invoice No.
A3: TEL:++84-4-3771-3682, FAX:++84-4-3771-3685 | I3: Date | J3: 45679
A7: REMIT TO: | F7: WIRE TO:
A8: BIP SYSTEMS VIETNAM CO.,LTD | F8: Name: | G8: BIP SYSTEMS VIETNAM CO.,LTD
A9: Room No 403, DMC Tower, 535 Kim Ma Str., Ba Dinh Dist Hanoi | F9: Bank: | G9: Sumitomo Mitsui Banking Corporation
F10: Address: | G10: Unit 1201, 12Fl, Lotte Centre 54 Lieu Giai Str., Ba Dinh, Hanoi , Vietnam
F11: A/C | G11: 1000747-2(JPY)
A15: SOLD TO:
A16: BIP SYSTEMS CORPORATION
A17: 3rd FL., BIEN QUAD, 9-1 SAKURAGAOKA-CHO, SHIBUYA, TOKYO, JAPAN
A18: ATTN:
A23: DESCRIPTION | F23: AMOUNT
A24: 1 | B24: Software Development Jan 2024 | F24: =+'2.Sep_24 '!H58 -> 600000
A25: 2 | B25: Software Development Feb 2024 | F25: =+'2.Oct_24'!H60 -> 0
A26: 3 | B26: Software Development Mar 2024 | F26: =+'2.Nov_24'!H66 -> 0
A27: 4 | B27: Software Development Apr 2024 | F27: =+'2.Dec_24'!H68 -> 0
A29: AMOUNT TO BE PAID
G31: BIP SYSTEMS Vietnam Co.,Ltd
G32: Director
H35: Takeshi Kashiwagi

Sheet Project Status
B4: Project Name | C4: Project outline | D4: Term | F4: Assigned | G4: Amount (billing amount on Jan/2025) | H4: Note
D5: Start | E5: End | G5: (JPY)
B6: SFDC-WOWOW | C6: Make data integration between new CRM system(SalesForce) and current CRM system(Wism/Logica). | D6: 45536 | E6: 45657 | F6: DungNT | G6: =500000*4*0.5 -> 1000000 | H6: Amount = 500,000 x 4 months x 50% activity. | I6: ✓
F7: TuanDH | G7: =350000*5/21+350000+350000*12/21 -> 633333.33 | H7: Amount = 350,000 x 5/21(Join 24/9/2024) + 350,000 x 1 month(Oct) + 350,000 x 12/21(Left on 19/11) | I7: ✓ | K7: 300000 | L7: =K7*4 -> 1200000 | M7: Bùi Hồng Khánh | N7: =G49 -> 0 | O7: =L7-N7 -> 1200000
F8: DatPV | I8: ✓ | K8: 430000 | L8: =K8*4 -> 1720000 | M8: Kiều Bảo Long | N8: =G37 -> 0 | O8: =L8-N8 -> 1720000
F9: QuanNM | I9: ✓ | K9: 300000 | L9: =K9*4 -> 1200000 | M9: Nguyễn Thành Trung | N9: =G20+G29 -> 0 | O9: =L9-N9 -> 1200000
F10: DungHTN | I10: ✓ | K10: 300000 | L10: =K10*4 -> 1200000 | M10: Nguyễn Thượng Minh | N10: =G54 -> 0 | O10: =L10-N10 -> 1200000
F11: (total) | G11: =SUM(G6:G10) -> 1633333.3 | K11: 300000 | L11: =K11*4 -> 1200000 | M11: Bùi Thị Thơm | N11: =G28+G39 -> 0 | O11: =L11-N11 -> 1200000
B12: SFDC-NGB | C12: Build Call-Center system for banking company | D12: 45536 | E12: 45657 | F12: DungNT | I12: ✓ | K12: 300000 | L12: =K12*4 -> 1200000 | M12: Nguyễn Minh Vũ | N12: =G31+G51 -> 0 | O12: =L12-N12 -> 1200000
F13: TrungNT | I13: ✓ | K13: 300000 | L13: =K13*4 -> 1200000 | M13: Phạm Long Quân | N13: =G52 -> 0 | O13: =L13-N13 -> 1200000
F14: TuanNA | I14: ✓ | K14: 300000 | L14: =K14*4 -> 1200000 | M14: Đỗ Tuấn Thành | N14: =G32 -> 0 | O14: =L14-N14 -> 1200000
F15: DungHTN | I15: ✓ | K15: 300000 | M15: Đỗ Tuấn Thành | O15: =L15-N15 -> 0
F16: (total) | G16: =SUM(G12:G15) -> 0 | K16: 250000 | L16: =K16*4 -> 1000000 | M16: Nguyễn Hải Anh | N16: =G42 -> 0 | O16: =L16-N16 -> 1000000
B17: mieten R&D | C17: Research and make prototype for adding new functionalities to mieten(security software) | D17: 45536 | E17: 45657 | F17: LongTT | I17: ✓ | K17: 430000 | L17: =K17*4 -> 1720000 | M17: Trần Tuấn Long | N17: =G17+G41 -> 0 | O17: =L17-N17 -> 1720000
F18: HienHT | I18: ✓ | K18: 250000 | L18: =K18*4 -> 1000000 | M18: Hoàng Quang Linh | N18: =G33 -> 0 | O18: =L18-N18 -> 1000000
F19: ChiLNQ | I19: ✓ | K19: 300000 | L19: =K19*4 -> 1200000 | M19: Trần Minh Hằng | N19: =G55+G36 -> 0 | O19: =L19-N19 -> 1200000
F20: TrungNT | I20: ✓ | K20: 250000 | L20: =K20*4 -> 1000000 | M20: Lưu Thị Hải Yến | N20: =G43 -> 0 | O20: =L20-N20 -> 1000000
F21: (total) | G21: =SUM(G17:G20) -> 0 | K21: 805000 | L21: =K21*4 -> 3220000 | M21: Nguyễn Tiến Dũng | N21: =G6+G12 -> 1000000 | O21: =L21-N21 -> 2220000
B22: mieten Step2 | C22: Add new functions which will be fixed in mieten R&D | D22: 45658 | E22: 45746 | F22: LongTT | K22: 370000 | L22: =K22*4 -> 1480000 | M22: Nguyễn Tiến Trung | N22: =G13 -> 0 | O22: =L22-N22 -> 1480000
F23: ChiLNQ | K23: 310000 | L23: =K23*4 -> 1240000 | M23: Nguyễn Anh Tuấn | N23: =G14 -> 0 | O23: =L23-N23 -> 1240000
F24: TrungNT | K24: 220000 | L24: =K24*4 -> 880000 | M24: Phạm Văn Đạt | N24: =G8 -> 0 | O24: =L24-N24 -> 880000
F25: (total) | G25: =SUM(G22:G24) -> 0 | K25: 250000 | L25: =K25*3+K25*9/22 -> 852272.73 | M25: Nguyễn Tuấn Anh | N25: =G44 -> 0 | O25: =L25-N25 -> 852272.73
B26: docomo data handling system | C26: Add new functionality(get user support data) to docomo remote support system. | D26: 45474 | E26: 45626 | F26: ThomBT | K26: 470000 | L26: =470000*5/21+470000+470000*12/21 -> 850476.19 | M26: Đỗ Hữu Tuấn | N26: =G7 -> 633333.33 | O26: =L26-N26 -> 217142.86
K27: 300000 | L27: =K27*2+K27*4/22 -> 654545.45 | M27: Lai Nguyệt Quế Chi | N27: =G19+G46 -> 0 | O27: =L27-N27 -> 654545.45
B28: docomo message system development | C28: Add new functionality(message sending/managing system to docomo remote support syystem. | D28: 45505 | E28: 45596 | F28: ThomBT | I28: ✓ | K28: 250000 | L28: =K28*2 -> 500000 | M28: Nguyễn Xuân Trường | N28: =G35 -> 0 | O28: =L28-N28 -> 500000
F29: TrungNT | I29: ✓ | K29: 300000 | L29: =K29*2 -> 600000 | M29: Nguyễn Anh Đức | N29: =G34 -> 0 | O29: =L29-N29 -> 600000
F30: (total) | K30: 250000 | L30: =K30*2 -> 500000 | M30: Trần Anh Đức | N30: =G56 -> 0 | O30: =L30-N30 -> 500000
B31: FSVM system development | C31: Develop chat functionality to FSVM system. | D31: 45505 | E31: 45747 | F31: VuNM | I31: ✓ | K31: 300000 | L31: =K31*2 -> 600000 | M31: Hoàng Thị Ngọc Dung | N31: =G10+G15 -> 0 | O31: =L31-N31 -> 600000
F32: ThanhDT | I32: ✓ | K32: Sub Total | L32: =SUM(L7:L31) -> 27417294 | N32: =SUM(N7:N31) -> 1633333.3 | O32: =L32-N32 -> 25783961
F33: LinhHQ | I33: ✓ | L33: 2400000 | M33: Kashiwagi | N33: 2400000
F34: Duc Nguyen | I34: ✓ | K34: Total | L34: =L32+L33 -> 29817294 | N34: =N32+N33 -> 4033333.3
F35: TruongNX | I35: ✓
F36: HangTM | I36: ✓ | K36: 300000 | L36: =K36*2 -> 600000 | M36: Hien | N36: =G45+G18 -> 0
F37: LongKB | I37: ✓ | K37: 370000 | L37: =K37 -> 370000 | M37: Quang(12/1 PS入社) | N37: =G9 -> 0
F38: (total)
B39: VAC | C39: Transfer the development tasks from another company. | D39: 45597 | E39: 45931 | F39: ThomBT | I39: ✓ | L39: =L34+L36+L37 -> 30787294 | N39: =N34+N36+N37 -> 4033333.3
B41: CiMA project | C41: Do the test of docomo applications. | D41: 45536 | E41: 45657 | F41: LongTT | I41: ✓ | L41: =SUM(L7:L24)+L26+L33+L36 -> 26710476 | M41: 請求書の額に一致
F42: HaiAnh | I42: ✓
F43: YenLTH | I43: ✓
F44: AnhNT | I44: ✓ | L44: {='3.請求書'!F29:J29} -> 0 | M44: 0 | N44: 0 | O44: 0 | P44: 0
...
